
<mujoco>
    <option density="1.204" viscosity="1.8e-5" integrator="implicit" />
    <visual>
        <global elevation="-10" />
    </visual>

    <asset>
        <texture name="grid" type="2d" builtin="checker" width="512" height="512" rgb2="0 0 0"
            rgb1="1 1 1" />
        <material name="grid" texture="grid" texrepeat="2 2" texuniform="true" reflectance=".6" />
    </asset>
    <worldbody>
        <geom name="ground" type="plane" size="5 5 .05" pos="0 0 -.05" material="grid" />
        <light pos="0 0 2" ambient="0.2 0.2 0.2"/>
        <light pos="0 1 2" ambient="0.2 0.2 0.2"/>
        <light pos="0 -1 2" ambient="0.2 0.2 0.2"/>
        <body name = "Torso" pos = "0 0 0.1">
            <geom name = "Torso" type = "box" size = "0.04 0.1 0.12" rgba = "0.2 0.4 0.5 1"/>
            <inertial pos="0 0 0" mass="0.72" fullinertia="0.00146 0.00096 0.0007 0 0 0"/>
            <freejoint name="root"/>
            <!-- Right Wheel-->
            <body name = "Right Wheel" pos = "0 -0.12 -0.1" euler = "90 0 0">
                <geom name = "Right Wheel" type = "cylinder" size = "0.045 0.015"/>
                <joint type="hinge" name = "Right Wheel Joint" axis = "0 0 1" pos = "0 0 0"/>
            </body>

            <body name = "Left Wheel" pos = "0 0.12 -0.1" euler = "90 0 0">
                <geom name = "Left Wheel" type = "cylinder" size = "0.045 0.015"/>
                <joint type="hinge" name = "Left Wheel Joint" axis = "0 0 1" pos = "0 0 0"/>
            </body>

        </body>
    </worldbody>
</mujoco>